Workbook

Sheet SOFP  10.18
A1: Magic Arun Hydropower Private Limitd
A2: Statement of Financial Position
A3: As at 18 Magh 2082
E4: Restated
C5: As at | D5: As at | E5: As at
B6: Notes | C6: 18 Magh 2082 | D6: 32 Ashadh 2082 | E6: 1 Shrawan 2081
A7: ASSETS
A8: Non-Current Assets
A9: Property, Plant and Equipment | B9: 3.1 | C9: ='3.1 10.18'!I44 -> 473888.75 | D9: ='3.1 10.18'!I42 -> 604474 | E9: 0 | G9: =+D9+D11 -> 604474 | H9: =+C9+C11 -> 473888.75
A10: Project in Progress (WIP) | B10: 3.1 | C10: ='3.1 10.18'!C70 -> 15814476 | D10: ='3.1 10.18'!F70 -> 12985641 | E10: ='3.1 10.18'!G50 -> 12985641
A11: Intangible Assets | B11: 3.2 | C11: ='[5]3.2'!E43 -> 0 | D11: ='[5]3.2'!E41 -> 0 | E11: ='[5]3.2'!E39 -> 0 | G11: 821236.13 | H11: =+'SOI 10.18'!C17 -> 130585.25
A12: Investments | B12: 3.3 | C12: ='[5]3.3'!C34 -> 0 | D12: ='[5]3.3'!D34 -> 0 | E12: ='[5]3.3'!E34 -> 0 | G12: =+G9-G11 -> -216762.13 | H12: =SUM(H9:H11) -> 604474
A13: Other Receivables | B13: 3.4 | C13: 0 | D13: 0 | E13: 0 | H13: 2699634.6 | I13: =+H12-H13 -> -2095160.6
A14: Total Non-Current Assets | C14: =SUM(C9:C13) -> 16288365 | D14: =SUM(D9:D13) -> 13590115 | E14: =SUM(E9:E13) -> 12985641
A15: Current Assets
A16: Investments | B16: 3.3 | C16: ='[5]3.3'!C35 -> 0 | D16: ='[5]3.3'!D35 -> 0 | E16: ='[5]3.3'!E35 -> 0
A17: Account receivables | B17: 3.4 | C17: ='3.4 to 3.6 ao 10.18'!C32 -> 21010112 | D17: ='3.4 to 3.6 ao 10.18'!D32 -> 15311962 | E17: ='3.4 to 3.6 ao 10.18'!E32 -> 21788699 | G17: AS per Tally
A18: Inventories | B18: 3.5 | D18: =+'3.4 to 3.6 ao 10.18'!D47 -> 0 | E18: =+'3.4 to 3.6 ao 10.18'!E47 -> 0 | G18: 10922985
A19: Cash and cash equivalents | B19: 3.6 | C19: ='3.4 to 3.6 ao 10.18'!C58 -> 12637.35 | D19: ='3.4 to 3.6 ao 10.18'!D58 -> 891197 | E19: ='3.4 to 3.6 ao 10.18'!E58 -> 67329
A20: Other current assets | B20: 3.7 | C20: =+'3.4 to 3.6 ao 10.18'!C68 -> 0 | D20: =+'3.4 to 3.6 ao 10.18'!D68 -> 0 | E20: =+'3.4 to 3.6 ao 10.18'!E68 -> 0
A21: Total Current Assets | C21: =SUM(C16:C20) -> 21022749 | D21: =SUM(D16:D20) -> 16203159 | E21: =SUM(E16:E20) -> 21856028
A22: Total Assets | C22: =C21+C14 -> 37311114 | D22: =D21+D14 -> 29793274 | E22: =E21+E14 -> 34841669
A23: EQUITY AND LIABILITIES
A24: Equity
A25: Share Capital | B25: 3.8 | C25: ='3.7 to 3.8 10.18'!D31 -> 10290000 | D25: ='3.7 to 3.8 10.18'!E31 -> 12600000 | E25: 0 | G25: 6175421.8 | H25: =+G25+D27 -> 5801845.8
A26: Calls in Advance | C26: ='3.7 to 3.8 10.18'!D38 -> 22500000 | D26: 0 | E26: ='3.7 to 3.8 10.18'!E38 -> 0
A27: Retained Earnings | B27: 3.9 | C27: ='3.7 to 3.8 10.18'!D47 -> -538061.25 | D27: ='3.7 to 3.8 10.18'!E47 -> -373576 | E27: ='3.7 to 3.8 10.18'!E45 -> -196480 | G27: -6165121.9 | H27: =+G27-D27 -> -5791545.9
A28: Total Equity | C28: =SUM(C25:C27) -> 32251939 | D28: =SUM(D25:D27) -> 12226424 | E28: =SUM(E25:E27) -> -196480 | H28: 79025.12
A29: Liabilities
A30: Non-Current Liabilities
A31: Loans and Borrowings | B31: 3.10 | C31: ='3.9 to 3.11 AO 10.18'!D25 -> 3870000 | D31: ='3.9 to 3.11 AO 10.18'!E25 -> 17165000 | E31: ='3.9 to 3.11 AO 10.18'!F25 -> 20756010
A32: Provision for Employee Benefits | C32: ='3.9 to 3.11 AO 10.18'!D36 -> 0 | D32: ='3.9 to 3.11 AO 10.18'!E36 -> 0 | E32: ='3.9 to 3.11 AO 10.18'!F36 -> 0
A33: Provisions | D33: 0 | E33: 0
A34: Total Non-Current Liabilities | C34: =SUM(C31:C33) -> 3870000 | D34: =SUM(D31:D33) -> 17165000 | E34: =SUM(E31:E33) -> 20756010
A35: Current Liabilities
A36: Loans and Borrowings | B36: 3.10 | C36: ='3.9 to 3.11 AO 10.18'!D26 -> 0 | D36: ='3.9 to 3.11 AO 10.18'!E26 -> 0 | E36: ='3.9 to 3.11 AO 10.18'!F26 -> 0
A37: Trade and other payables | B37: 3.11 | C37: ='3.9 to 3.11 AO 10.18'!D49+'3.9 to 3.11 AO 10.18'!D61 -> 1189175 | D37: ='3.9 to 3.11 AO 10.18'!E49 -> 401850 | E37: ='3.9 to 3.11 AO 10.18'!F49 -> 28498
A38: Income Tax Liability | C38: ='3.9 to 3.11 AO 10.18'!D69 -> 0 | D38: ='3.9 to 3.11 AO 10.18'!E69 -> 0 | E38: ='3.9 to 3.11 AO 10.18'!F69 -> 0
A39: Provision for Employee Benefits | C39: 0 | D39: 0 | E39: 0
A40: Provisions | C40: 0 | D40: 0 | E40: 0
...

Sheet SOI 10.18
A1: ='SOFP 10.18'!A1 -> Magic Arun Hydropower Private Limitd
A3: Statement of Income
A4: For the Year Ended 18 Magh 2082
D5: Figures in NPR
D6: Restated
A7: Particulars | B7: Notes | C7: Upto 18 Magh 2082 | D7: FY 2081-82
A8: Revenue from Operations | B8: 3.12 | C8: ='3.12 to 3.18 ao 10.18'!D12 -> 0 | D8: ='3.12 to 3.18 ao 10.18'!E12 -> 0 | G8: =C8-D8 -> 0 | H8: =G8/D8 -> #DIV/0!
A9: Interest Income | C9: 0 | D9: 0
A10: Other Income | B10: 3.13 | C10: ='3.12 to 3.18 ao 10.18'!D21 -> 0 | D10: ='3.12 to 3.18 ao 10.18'!E21 -> 0
A11: Total Income | C11: =SUM(C8:C10) -> 0 | D11: =SUM(D8:D10) -> 0
A12: Material Consumed Expenses | B12: 3.14 | C12: ='3.12 to 3.18 ao 10.18'!D30 -> 0 | D12: ='3.12 to 3.18 ao 10.18'!E30 -> 0 | E12: =(C12+C13)/C8 -> #DIV/0! | F12: =(D12+D13)/D8 -> #DIV/0! | G12: =C12-D12 -> 0 | H12: =G12/D12 -> #DIV/0!
A13: Direct Expenses | B13: 3.15 | C13: =+'3.12 to 3.18 ao 10.18'!D38 -> 0 | D13: =+'3.12 to 3.18 ao 10.18'!E38 -> 0 | G13: =C13-D13 -> 0 | H13: =G13/D13 -> #DIV/0!
A14: Employee Benefit Expenses | B14: 3.16 | C14: =+'3.12 to 3.18 ao 10.18'!D50 -> 0 | D14: =+'3.12 to 3.18 ao 10.18'!E50 -> 0 | G14: =C14-D14 -> 0 | H14: =G14/D14 -> #DIV/0!
A15: Administrative and Other Expenses | B15: 3.17 | C15: ='3.12 to 3.18 ao 10.18'!D81 -> 33900 | D15: ='3.12 to 3.18 ao 10.18'!E81 -> 29382 | G15: =C15-D15 -> 4518 | H15: =G15/D15 -> 0.15376761
A16: Interest Expenses | B16: 3.18 | C16: ='3.12 to 3.18 ao 10.18'!D86 -> 0 | D16: ='3.12 to 3.18 ao 10.18'!E86 -> 0 | G16: =C16-D16 -> 0 | H16: =G16/D16 -> #DIV/0!
A17: Depreciation and Amortization Expenses | B17: 3.1 & 3.2 | C17: =+'3.1 10.18'!I30+'[5]3.2'!E32 -> 130585.25 | D17: =+'3.1 10.18'!I28+'[5]3.2'!E30 -> 147714 | E17: 187078.71 | F17: =+D17-E17 -> -39364.71 | G17: =C17-D17 -> -17128.75 | H17: =G17/D17 -> -0.11595888
A18: Total Expenses | C18: =SUM(C12:C17) -> 164485.25 | D18: =SUM(D12:D17) -> 177096
A19: Profit Before Tax | C19: =C11-C18 -> -164485.25 | D19: =D11-D18 -> -177096 | E19: -2368782.9 | F19: =+D19-E19 -> 2191686.9
A20: Income Tax Expense | C20: =SUM(C21:C22) -> 0 | D20: =SUM(D21:D22) -> 0
A21: Current year | C21: 0 | D21: 0
A22: Previous years | C22: 0 | D22: 0
A23: Net Profit for the year | C23: =C19-C20 -> -164485.25 | D23: =D19-D20 -> -177096

Sheet SOCE 10.18
A1: ='SOI 10.18'!A1 -> Magic Arun Hydropower Private Limitd
A3: Statement of Changes in Equity
A4: ='SOI 10.18'!A4 -> For the Year Ended 18 Magh 2082
G6: Figures in NPR
A7: Particulars | C7: Share Capital | D7: Calls in Advance | E7: Retained Earnings | F7: Other Reserves | G7: Total
A8: Balance at 1 Shrawan 2081 | C8: =+'SOFP 10.18'!E25 -> 0 | D8: 7600000 | E8: =+'3.7 to 3.8 10.18'!E45 -> -196480 | F8: 0 | G8: =SUM(C8:F8) -> 7403520
A9: Restatements on transition to NAS for MEs | C9: 0 | D9: 0 | E9: =SUM([5]Reco!F5:F8) -> 0 | F9: 0 | G9: =SUM(C9:F9) -> 0
A10: Balance at 1 Shrawan 2081 (restated) | C10: =SUM(C8:C9) -> 0 | D10: =SUM(D8:D9) -> 7600000 | E10: =SUM(E8:E9) -> -196480 | F10: =SUM(F8:F9) -> 0 | G10: =SUM(G8:G9) -> 7403520 | H10: ='SOFP 10.18'!E28 -> -196480 | I10: =G10-H10 -> 7600000
A11: Profit for the year | C11: 0 | D11: 0 | E11: ='SOI 10.18'!D23 -> -177096 | F11: 0 | G11: =+SUM(C11:F11) -> -177096
A12: Issue of Shares | C12: 12600000 | D12: -7600000 | E12: 0 | F12: 0 | G12: =+SUM(C12:F12) -> 5000000
A13: Dividends to Shareholders | C13: 0 | D13: 0 | E13: 0 | F13: 0 | G13: =+SUM(C13:F13) -> 0
A14: Other Changes | C14: 0 | D14: 0 | E14: 0 | F14: 0 | G14: =+SUM(C14:F14) -> 0
A15: Balance at 32 Ashad 2082 | C15: =SUM(C10:C14) -> 12600000 | D15: =SUM(D10:D14) -> 0 | E15: =SUM(E10:E14) -> -373576 | F15: =SUM(F10:F14) -> 0 | G15: =SUM(G10:G14) -> 12226424 | H15: ='SOFP 10.18'!D28 -> 12226424 | I15: =G15-H15 -> 0
A16: Profit for the year | C16: 0 | D16: 0 | E16: =+'SOI 10.18'!C23 -> -164485.25 | F16: 0 | G16: =+SUM(C16:F16) -> -164485.25
A17: Issue of Shares | C17: 0 | D17: 0 | E17: 0 | F17: 0 | G17: =+SUM(C17:F17) -> 0
A18: Dividends to Shareholders | C18: 0 | D18: 0 | E18: 0 | F18: 0 | G18: =+SUM(C18:F18) -> 0
A19: Other Changes | C19: 0 | D19: 0 | E19: 0 | F19: 0 | G19: =+SUM(C19:F19) -> 0
A20: Balance at 32 Ashad 2083 | C20: =SUM(C15:C19) -> 12600000 | D20: =SUM(D15:D19) -> 0 | E20: =SUM(E15:E19) -> -538061.25 | F20: =SUM(F15:F19) -> 0 | G20: =SUM(G15:G19) -> 12061939 | H20: ='SOFP 10.18'!C28 -> 32251939 | I20: =G20-H20 -> -20190000

Sheet SCF 10.18
A1: ='SOCE 10.18'!A1 -> Magic Arun Hydropower Private Limitd
A3: Statement of Cash Flows
A4: ='SOCE 10.18'!A4 -> For the Year Ended 18 Magh 2082
C5: Figures in NPR
A6: Particulars | B6: ='SOI 10.18'!C7 -> Upto 18 Magh 2082 | C6: ='SOI 10.18'!D7 -> FY 2081-82
A7: CASH FLOWS FROM OPERATING ACTIVITIES
A8: Profit for the year | B8: ='SOI 10.18'!C19 -> -164485.25 | C8: ='SOI 10.18'!D19 -> -177096 | D8: =B8-'SOFP 10.18'!J27 -> -164485.25
A9: Adjustment for:
A10: Depreciation/Impairment on Property, Plant and Equipment | B10: ='SOI 10.18'!C17 -> 130585.25 | C10: ='SOI 10.18'!D17 -> 147714
A11: Interest Income
A12: Interest Expense | B12: ='SOI 10.18'!C16 -> 0 | C12: ='SOI 10.18'!D16 -> 0
A13: Loss/(gain) on sale of Property, Plant and Equipment
A14: Income Tax expense charged to statement of income
A15: Working Capital Adjustments
A16: Decrease/(Increase) in trade and other receivables | B16: ='SOFP 10.18'!J17+'SOFP 10.18'!J20 -> 0 | C16: ='SOFP 10.18'!E17-'SOFP 10.18'!D17 -> 6476737
A17: Decrease/(Increase) in Inventories | B17: ='SOFP 10.18'!J18 -> 0 | C17: ='SOFP 10.18'!K18 -> 0
A18: Increase/(Decrease) in trade and other payables | B18: ='SOFP 10.18'!J37 -> 0 | C18: ='SOFP 10.18'!K37 -> 0
A19: Increase/(Decrease) Loan and Borrowings | C19: ='SOFP 10.18'!D31-'SOFP 10.18'!E31 -> -3591010
A20: Increase/(Decrease) in other liabilities | C20: 0
A21: Cash Generated from Operations | B21: =SUM(B8:B20) -> -33900 | C21: =SUM(C8:C20) -> 2856345
A22: Interest paid | C22: 0
A23: Income tax paid | C23: 0
A24: NET CASH FLOWS FROM OPERATING ACTIVITIES (A) | B24: =SUM(B21:B23) -> -33900 | C24: =SUM(C21:C23) -> 2856345
A25: CASH FLOW FROM INVESTING ACTIVITIES
A26: Proceeds from sale of PPE, Investments/Financial Assets | C26: =-'3.1 10.18'!I8 -> 0
A27: Increase in project WIP | B27: ='SOFP 10.18'!J12 -> 0 | C27: =-'SOFP 10.18'!D10+'SOFP 10.18'!E10 -> 0
A28: Acquisition of Property, Plant and Equipment | B28: =-'3.1 10.18'!I15-'[5]3.2'!E17 -> 0 | C28: =-'3.1 10.18'!I10-'[5]3.2'!E12 -> -752188
A29: NET CASH FLOWS FROM INVESTING ACTIVITIES (B) | B29: =SUM(B25:B28) -> 0 | C29: =SUM(C25:C28) -> -752188
A30: CASH FLOW FROM FINANCING ACTIVITIES
A31: Proceeds from the issue of Equity and Preference Share | C31: ='SOFP 10.18'!D25-'SOFP 10.18'!E26 -> 12600000
A32: Proceeds from loans and borrowings borrowings | B32: ='SOFP 10.18'!J36 -> 0 | C32: ='SOFP 10.18'!K36 -> 0
A33: Interest Expenses | B33: =-B12 -> 0 | C33: =-C12 -> 0
A34: Dividend Paid
A35: NET CASH FLOW FROM FINANCING ACTIVITIES (C) | B35: =SUM(B31:B34) -> 0 | C35: =SUM(C31:C34) -> 12600000
A36: Net Increase in Cash and Cash Equivalents | B36: =B24+B29+B35 -> -33900 | C36: =C24+C29+C35 -> 14704157
A37: Cash and Cash Equivalents at the beginning | B37: ='SOFP 10.18'!D19 -> 891197 | C37: ='SOFP 10.18'!E19 -> 67329
A38: Exchange gains/(losses) in cash and cash equivalents
A39: Cash and Cash Equivalents at the end | B39: =B36+B37 -> 857297 | C39: =C36+C37 -> 14771486
B40: ='3.4 to 3.6 ao 10.18'!C58 -> 12637.35 | C40: ='3.4 to 3.6 ao 10.18'!D58 -> 891197
B41: =B39-B40 -> 844659.65 | C41: =C39-C40 -> 13880289

Sheet 3.1 10.18
A1: ='SOFP 10.18'!A1 -> Magic Arun Hydropower Private Limitd
A2: Notes to Financial Statements
I3: Figures in NPR
A4: 3.1 | B4: Property, Plant and Equipment
C5: Furniture & Fixtures | D5: Computer | E5: Office Equipments | F5: Vehicles | G5: Plant and Machinery | H5: Office Furnishing | I5: Total
B6: Cost
B8: Balance at 1 Shrawan 2081 | C8: 0 | D8: 0 | E8: 0 | F8: 0 | G8: 0 | I8: =SUM(C8:G8) -> 0
I9: =SUM(C9:G9) -> 0
B10: Additions | C10: 532188 | D10: 0 | E10: 0 | F10: 220000 | G10: 0 | I10: =SUM(C10:G10) -> 752188
B11: Disposals | C11: 0 | D11: 0 | E11: 0 | F11: 0 | G11: 0 | I11: =SUM(C11:G11) -> 0
B13: Balance at 32 Ashadh 2082 | C13: =SUM(C8:C11) -> 532188 | D13: =SUM(D8:D11) -> 0 | E13: =SUM(E8:E11) -> 0 | F13: =SUM(F8:F11) -> 220000 | G13: =SUM(G8:G11) -> 0 | I13: =SUM(I8:I11) -> 752188
B15: Additions | C15: 0 | E15: 0 | G15: 0 | I15: =SUM(C15:G15) -> 0
B16: Disposals | C16: 0 | D16: 0 | E16: 0 | F16: 0 | G16: 0 | I16: =SUM(C16:G16) -> 0
B18: Balance at 18 Magh 2082 | C18: =SUM(C13:C16) -> 532188 | D18: =SUM(D13:D16) -> 0 | E18: =SUM(E13:E16) -> 0 | F18: =SUM(F13:F16) -> 220000 | G18: =SUM(G13:G16) -> 0 | H18: =SUM(H13:H16) -> 0 | I18: =SUM(C18:G18) -> 752188
B21: Accumulated depreciation
B23: =B8 -> Balance at 1 Shrawan 2081 | C23: 0 | D23: 0 | E23: 0 | F23: 0 | G23: 0 | I23: =SUM(C23:G23) -> 0
B25: Charge for the year | C25: 133047 | D25: 0 | E25: 0 | F25: 14667 | G25: 0 | H25: 0 | I25: =SUM(C25:H25) -> 147714
B26: Disposals
B28: =B13 -> Balance at 32 Ashadh 2082 | C28: =SUM(C23:C26) -> 133047 | D28: =SUM(D23:D26) -> 0 | E28: =SUM(E23:E26) -> 0 | F28: =SUM(F23:F26) -> 14667 | G28: =SUM(G23:G26) -> 0 | H28: =SUM(H23:H26) -> 0 | I28: =SUM(I23:I26) -> 147714
B30: Charge for the year | C30: =(C13-C25)*25% -> 99785.25 | E30: 0 | F30: 30800 | G30: 0 | H30: =(H18-H28)*15% -> 0 | I30: =SUM(C30:G30) -> 130585.25
B31: Disposals
B33: =B18 -> Balance at 18 Magh 2082 | C33: =C30+C28 -> 232832.25 | D33: =SUM(D28:D31) -> 0 | E33: =SUM(E28:E31) -> 0 | F33: =F30+F28 -> 45467 | G33: =SUM(G28:G31) -> 0 | H33: =SUM(H28:H31) -> 0 | I33: =SUM(C33:G33) -> 278299.25
B38: Net Book Value
B40: As at 1st Shrawan 2081 | C40: =C8-C23 -> 0 | D40: =D8-D23 -> 0 | E40: =E8-E23 -> 0 | F40: =F8-F23 -> 0 | G40: =G8-G23 -> 0 | H40: =H8-H23 -> 0 | I40: =I8-I23 -> 0
B42: As at 32nd Ashad 2082 | C42: =C13-C28 -> 399141 | D42: =D13-D28 -> 0 | E42: =E13-E28 -> 0 | F42: =F13-F28 -> 205333 | G42: =G13-G28 -> 0 | H42: =H13-H28 -> 0 | I42: =SUM(C42:G42) -> 604474
B44: As at 10 Magh 2082 | C44: =C18-C33 -> 299355.75 | D44: =D18-D33 -> 0 | E44: =E18-E33 -> 0 | F44: =F18-F33 -> 174533 | G44: =G18-G33 -> 0 | H44: =H18-H33 -> 0 | I44: =SUM(C44:G44) -> 473888.75
B48: 3.1.2 Project in Progress (WIP)
B49: Particulars | C49: As on 10 Magh 2082 | E49: During the period | G49: 2080.081
B50: Project Initial Expenses | C50: =C70 -> 15814476 | E50: =D70 -> 2828835 | G50: =F70 -> 12985641
C52: As on 10 Magh 2082 | D52: During the period | F52: 2081-82
B53: Survey License Fee | C53: =F53+D53 -> 8000000 | D53: ='TB update upto 10.18'!E59 -> 0 | F53: ='TB update upto 10.18'!C59 -> 8000000
B54: License Renewal Fee | C54: =F54+D54 -> 2000000 | D54: ='TB update upto 10.18'!E60 -> 2000000 | F54: ='TB update upto 10.18'!C60 -> 0
B55: PPA Fee | C55: =F55+D55 -> 300000 | D55: ='TB update upto 10.18'!E61 -> 0 | F55: ='TB update upto 10.18'!C61 -> 300000
B56: Grid Impat Study Expenses (NEA) | C56: =F56+D56 -> 102000 | D56: ='TB update upto 10.18'!E62 -> 0 | F56: ='TB update upto 10.18'!C62 -> 102000
B57: Bank Charges | C57: =F57+D57 -> 274657.15 | D57: ='TB update upto 10.18'!E63 -> 0 | F57: ='TB update upto 10.18'!C63 -> 274657.15
B58: ERC Approval | C58: =F58+D58 -> 197000 | D58: ='TB update upto 10.18'!E64 -> 0 | F58: ='TB update upto 10.18'!C64 -> 197000
B59: Salary Expenses | C59: =F59+D59 -> 2990000 | D59: ='TB update upto 10.18'!E65 -> 415000 | F59: ='TB update upto 10.18'!C65 -> 2575000
B60: Travelling & Site Visit Expenses | C60: =F60+D60 -> 808129 | D60: ='TB update upto 10.18'!E66 -> 343785 | F60: ='TB update upto 10.18'!C66 -> 464344
B61: Labour Wages | C61: =F61+D61 -> 660000 | D61: ='TB update upto 10.18'!E67 -> 0 | F61: ='TB update upto 10.18'!C67 -> 660000
B62: Office Rent | C62: =F62+D62 -> 240000 | D62: ='TB update upto 10.18'!E68 -> 0 | F62: ='TB update upto 10.18'!C68 -> 240000
...

Sheet 3.4 to 3.6 ao 10.18
A1: ='SOFP 10.18'!A1 -> Magic Arun Hydropower Private Limitd
A2: Notes to Financial Statements
D4: Figures in NPR
A6: 3.4 | B6: Account Receivables | C6: ='[5]3.3'!C29 -> As at | D6: ='[5]3.3'!D29 -> As at | E6: ='[5]3.3'!E29 -> As at
C7: 18 Magh 2082 | D7: ='[5]3.3'!D30 -> 32 Ashadh 2082 | E7: ='[5]3.3'!E30 -> 1 Shrawan 2081
B9: Account Receivables
B10: Advance for Road Construction | C10: 0 | D10: 0 | E10: 1000000
B11: Advance for Land Purchase | C11: 0 | D11: 0 | E11: 20300000
B12: Site Advance | C12: 0 | D12: 0 | E12: 488699
B13: Other Receivables
B14: Bijaya Bista | C14: ='TB update upto 10.18'!G78 -> 5000000 | D14: 4000000
B15: Ellite Powers Pvt.Ltd | C15: 0 | D15: 3000000
B16: Environment Partners Pvt.Ltd | C16: ='TB update upto 10.18'!G94 -> 250000 | D16: 250000
B17: Rajendra Karki- Advance | C17: ='TB update upto 10.18'!G80 -> 5563462 | D17: 5563462
B18: Slesha Engineering Consultancy Pvt.Ltd | C18: ='TB update upto 10.18'!G93 -> 2900000 | D18: 2200000 | E18: 0
B19: Ellite Steel Pvt.ltd | C19: ='TB update upto 10.18'!G84 -> 260000
B20: Buddha Law Associates | C20: ='TB update upto 10.18'!G96 -> 75000
B21: Other Receivables | C21: ='TB update upto 10.18'!G95+'TB update upto 10.18'!G45 -> 133525
B22: Samyak Consulting Pvt. Ltd. | C22: ='TB update upto 10.18'!G92 -> 529624.5
B23: Bahadur Ventures Pvt. Ltd. | C23: ='TB update upto 10.18'!G50 -> 5000000
B24: Pramod Neupane | C24: ='TB update upto 10.18'!G79 -> 500000
B25: kanchan Sherpa | C25: ='TB update upto 10.18'!G90 -> 500000
B27: Deposit
B28: Cash Margin-PB-NEA | C28: ='TB update upto 10.18'!G100 -> 298500 | D28: 298500 | E28: 0
C29: =+C12+SUM(C14:C28) -> 21010112 | D29: =SUM(D10:D28) -> 15311962 | E29: =SUM(E10:E18) -> 21788699
B31: Non-current portion | C31: 0 | D31: 0 | E31: 0
B32: Current portion | C32: =C29 -> 21010112 | D32: =D29 -> 15311962 | E32: =E29 -> 21788699
B34: Provision for impairment of trade receivables: | D34: FY | E34: FY
D35: 2081-82 | E35: 2080-81
B36: Balance at the beginning of the year | D36: 0 | E36: 0
B37: Provided during the year | D37: 0 | E37: 0
B38: Written off during the year | D38: 0 | E38: 0
B39: Unused provisions reversed | D39: 0 | E39: 0
B41: Balance at the end of the year | D41: =SUM(D36:D39) -> 0 | E41: =SUM(E36:E39) -> 0
A43: 3.5 | B43: Inventories
C44: =C6 -> As at | D44: =D6 -> As at | E44: =E6 -> As at
C45: =C7 -> 18 Magh 2082 | D45: =D7 -> 32 Ashadh 2082 | E45: =E7 -> 1 Shrawan 2081
B47: Inventories of goods held for resale | C47: ='3.12 to 3.18 ao 10.18'!D28 -> 0 | D47: 0 | E47: 0
C49: =C47 -> 0 | D49: =D47 -> 0 | E49: =E47 -> 0
A50: 3.6 | B50: Cash and Cash Equivalents
...

Sheet 3.7 to 3.8 10.18
A1: ='[5]3.3'!A1:E1 -> CELER MART PVT. LTD.
B3: Notes to Financial Statements
E5: Figures in NPR
A7: 3.7 | B7: Share Capital
D8: ='3.4 to 3.6 ao 10.18'!D6 -> As at | E8: ='3.4 to 3.6 ao 10.18'!E6 -> As at
D9: ='3.4 to 3.6 ao 10.18'!C7 -> 18 Magh 2082 | E9: ='3.4 to 3.6 ao 10.18'!D7 -> 32 Ashadh 2082
B11: Authorized
B12: 260,000 ordinary shares of NPR 100 each | D12: 26000000 | E12: =D12 -> 26000000
B14: Ordinary Shares Issued and Fully Paid
B15: Ordinary shares of Rs. 100 each
D16: Ordinary | E16: Ordinary
D17: share | E17: share capital
D18: As at | E18: As at
D19: 18 Magh 2082 | E19: 32 Ashadh 2082
B20: Paid up Share capital
B21: Bijay Bista | E21: 3200000
B22: Rajendra Karki | D22: ='TB update upto 10.18'!H10 -> 890000 | E22: 3200000
B23: Kanchan Sherpa | E23: 200000
B24: Lilamani Pathak | E24: 1000000
B25: Bhadra Ventures Pvt.LTD | E25: 5000000
B26: Shivaram Bhandari | D26: ='TB update upto 10.18'!H15 -> 5000000
B27: Indu Bhandari Basnet | D27: ='TB update upto 10.18'!H16 -> 2510000
B28: Nabaraj Tiwari | D28: ='TB update upto 10.18'!H17 -> 1260000
B29: Murali Adhikari | D29: ='TB update upto 10.18'!H18 -> 630000
B31: Total | D31: =SUM(D21:D30) -> 10290000 | E31: =SUM(E21:E30) -> 12600000
D32: As at | E32: As at
B33: Share Advance | D33: 10 Magh 2082 | E33: 32 Ashadh 2082
B34: Shiv Ram Bhandari | D34: ='TB update upto 10.18'!H20 -> 20000000
B35: Bond Construction | D35: ='TB update upto 10.18'!H21 -> 2000000
B36: Uttam Kumar | D36: ='TB update upto 10.18'!H22 -> 500000
B37: Lilamani Pathak
B38: Total | D38: =SUM(D34:D37) -> 22500000 | E38: =SUM(E34:E37) -> 0
A40: 3.8 | B40: Retained Earnings
D42: =D8 -> As at | E42: =E8 -> As at
D43: ='SOFP 10.18'!C6 -> 18 Magh 2082 | E43: ='SOFP 10.18'!D6 -> 32 Ashadh 2082 | G43: New | J43: Old
B45: Opening balance | D45: =+E47 -> -373576 | E45: -196480 | G45: =+E45 -> -196480 | J45: =+E45 -> -196480
B46: Net profit for the year | D46: ='SOI 10.18'!C23 -> -164485.25 | E46: ='SOI 10.18'!D23 -> -177096 | G46: -2368782.9 | J46: =+'SOI 10.18'!E19 -> -2368782.9
B47: Closing balance | D47: =SUM(D45:D46) -> -538061.25 | E47: =SUM(E45:E46) -> -373576 | G47: =SUM(G45:G46) -> -2565262.9 | H47: As per FS | J47: =+J45+J46 -> -2565262.9
G48: =+#REF!+#REF! -> #REF! | H48: AS per Tally
E49: =+E47-G47 -> 2191686.9 | G49: =+G47+G48 -> #REF!

Sheet 3.9 to 3.11 AO 10.18
A1: ='[5]3.3'!A1:E1 -> CELER MART PVT. LTD.
A3: Notes to Financial Statements
F5: Figures in NPR
A7: 3.9 | B7: Loans and Borrowings
C8: As at | D8: ='3.7 to 3.8 10.18'!D8 -> As at | E8: ='3.7 to 3.8 10.18'!E8 -> As at | F8: =E8 -> As at
C9: 15 Asadh 2083 | D9: ='SOFP 10.18'!C6 -> 18 Magh 2082 | E9: ='SOFP 10.18'!D6 -> 32 Ashadh 2082 | F9: ='SOFP 10.18'!E6 -> 1 Shrawan 2081
B10: Total Loans and Borrowings
B11: Bank Overdraft | D11: 0 | E11: 0 | F11: 0
B12: Short Term Payable | D12: 0 | E12: 0 | F12: 20756010
B13: Basudev Dhiktta | D13: ='TB update upto 10.18'!H49 -> 2200000 | E13: 2200000
B14: Bhadra Ventures Pvt.Ltd | D14: 0 | E14: 1300000
B15: Eak Raj Khatiwada | E15: 12000000
B16: Naresh Poudel-Payable | D16: ='TB update upto 10.18'!H40 -> 390000 | E16: 365000
B17: Sandipa Thapa | D17: ='TB update upto 10.18'!H41 -> 200000 | E17: 200000
B18: Shyam Prasad Kuikel | D18: ='TB update upto 10.18'!H42 -> 500000 | E18: 500000
B19: Ellite Wire Pvt.Ltd | D19: ='TB update upto 10.18'!H47 -> 380000 | E19: 600000
B20: Ellite Powers Pvt.Ltd | D20: ='TB update upto 10.18'!H89 -> 200000 | E20: 0
D23: =SUM(D11:D20) -> 3870000 | E23: =SUM(E11:E20) -> 17165000 | F23: =SUM(F11:F19) -> 20756010
B25: Non-current loans and borrowings | D25: =D23-D26 -> 3870000 | E25: =E23-E26 -> 17165000 | F25: =F23-F26 -> 20756010
B26: Current loans and borrowings | D26: =D11 -> 0 | E26: =E11 -> 0 | F26: =F11 -> 0
A29: 3.10 | B29: Provision for Employee Benefits
C31: =C8 -> As at | D31: =D8 -> As at | E31: =E8 -> As at | F31: =F8 -> As at
C32: =C9 -> 15 Asadh 2083 | D32: =D9 -> 18 Magh 2082 | E32: =E9 -> 32 Ashadh 2082 | F32: =F9 -> 1 Shrawan 2081
B34: Provision for Gratuity | D34: 0 | E34: 0
B35: Provision for Leave benefits
D36: =SUM(D34:D35) -> 0 | E36: =SUM(E34:E35) -> 0 | F36: =SUM(F34:F35) -> 0
A38: 3.11 | B38: Trade and other payables
C39: =C31 -> As at | D39: =D31 -> As at | E39: =E31 -> As at | F39: =F31 -> As at
C40: =C32 -> 15 Asadh 2083 | D40: =D32 -> 18 Magh 2082 | E40: =E32 -> 32 Ashadh 2082 | F40: =F32 -> 1 Shrawan 2081
B41: TDS on Audit Fee | D41: ='TB update upto 10.18'!H26 -> 825 | E41: 375 | F41: 375
B42: TDS on Salary (SST) | D42: ='TB update upto 10.18'!H27 -> 29900 | E42: 25750 | F42: 248
B43: TDS on Office Rent | D43: ='TB update upto 10.18'!H30 -> 24000 | E43: 24000 | F43: 0 | G43: Net of TDS
B44: TDS on Labour Wages | D44: ='TB update upto 10.18'!H31 -> 6600 | E44: 6600 | F44: 0
B45: Audit Fee Payable | D45: ='TB update upto 10.18'!H33 -> 61325 | E45: 27875 | F45: 27875
B46: Staff Payable | D46: ='TB update upto 10.18'!H37 -> 222750 | E46: 222750 | F46: 0
B47: Office Rent Payable | D47: ='TB update upto 10.18'!H38 -> 94500 | E47: 94500 | F47: 0
B48: TDS on Meeting Fee | D48: ='TB update upto 10.18'!H28 -> 7275
D49: =SUM(D41:D48) -> 447175 | E49: =SUM(E41:E47) -> 401850 | F49: =SUM(F41:F47) -> 28498
B50: Other payable
B51: =[5]Sheet1!A8 -> Sita Karki | D51: ='TB update upto 10.18'!H44 -> 700000
...

Sheet 3.12 to 3.18 ao 10.18
A1: ='[5]3.3'!A1:E1 -> CELER MART PVT. LTD.
A3: Notes to Financial Statements
E5: Figures in NPR
A7: 3.12 | B7: Revenue from Operations
D8: ='SOI 10.18'!C7 -> Upto 18 Magh 2082 | E8: ='SOI 10.18'!D7 -> FY 2081-82
B9: Sale of goods | D9: 0 | E9: 0 | G9: 79597.18 | H9: 1182752.6
B10: Rendering of services
D12: =SUM(D9:D10) -> 0 | E12: =SUM(E9:E10) -> 0
A15: 3.13 | B15: Other income
D16: =D8 -> Upto 18 Magh 2082 | E16: =E8 -> FY 2081-82
B17: Commission and incentive | D17: 0
B18: Discounts Received | D18: 0 | E18: 0
B19: Exchange gain | D19: 0
D21: =SUM(D17:D19) -> 0 | E21: =SUM(E17:E19) -> 0
A24: 3.14 | B24: Material Consumed Expenses
D25: =D8 -> Upto 18 Magh 2082 | E25: =E8 -> FY 2081-82
B26: Balance on 1 Shrawan | D26: =E28 -> 0 | E26: 0
B27: Purchase during the period | D27: 0 | E27: 0 | G27: 120571
B28: Less: Balance on 32 Ashadh | D28: 0 | E28: 0
D30: =D26+D27-D28 -> 0 | E30: =E26+E27-E28 -> 0
A32: 3.15 | B32: Direct Expenses
D33: =D66 -> Upto 18 Magh 2082 | E33: =E66 -> FY 2081-82
B34: Freight
B35: Customs Duty
B36: Other Direct Expenses
D38: =SUM(D34:D36) -> 0 | E38: =SUM(E34:E36) -> 0
A41: 3.16 | B41: Employee Benefit Expenses
D42: =D25 -> Upto 18 Magh 2082 | E42: =E25 -> FY 2081-82
B43: Salary & Allowances | D43: 0 | E43: 0
B44: Dashain Expenses
B45: Staff Welfare
B46: PF & Gratuity expense | G46: =58914+49076 -> 107990
B47: Leave Expense
D50: =SUM(D43:D48) -> 0 | E50: =SUM(E43:E47) -> 0
B52: Key management personnel compensation
B53: Key management personnel are those persons having authority and responsibility for planning, directing and controlling the activities of the entity, including the directors.
D55: =D42 -> Upto 18 Magh 2082 | E55: =E42 -> FY 2081-82
B56: Salary
B57: Other long-term benefits
B58: Total pension and other post-employment benefit costs
...

Sheet 3.19 to 3.20 ao.10.18
A1: ='[5]3.3'!A1:E1 -> CELER MART PVT. LTD.
C2: `
A3: Notes to Financial Statements
D5: Figures in NPR
A7: 3.19 | B7: Other Expenses
C8: ='3.12 to 3.18 ao 10.18'!D8 -> Upto 18 Magh 2082 | D8: ='3.12 to 3.18 ao 10.18'!E8 -> FY 2081-82
B9: Loss on sale of investments | D9: 0
C12: =SUM(C10:C10) -> 0 | D12: =SUM(D9:D10) -> 0
A14: 3.2 | B14: Tax Expenses
C15: =C8 -> Upto 18 Magh 2082 | D15: =D8 -> FY 2081-82
B16: Tax on profit for the year | C16: ='Tax Computation 10.18'!C16 -> 0 | D16: ='SOI 10.18'!D21 -> 0
B17: Previous year tax | C17: 0 | D17: ='SOI 10.18'!D22 -> 0
C19: =SUM(C16:C17) -> 0 | D19: =SUM(D16:D17) -> 0
B21: Reconciliation of book profits and taxable profits
C22: =C15 -> Upto 18 Magh 2082 | D22: =D15 -> FY 2081-82
B23: Profit before tax as per books | C23: ='Tax Computation 10.18'!C3 -> -164485.25 | D23: ='SOI 10.18'!D19 -> -177096
B24: Add: Depreciation as per books | C24: ='Tax Computation 10.18'!C4 -> 130585.25 | D24: ='SOI 10.18'!D17 -> 147714
B25: Less: Depreciation as per tax | C25: ='Tax Computation 10.18'!C5 -> 0 | D25: =-D24 -> -147714
B26: Add: Disallowed repairs | C26: ='Tax Computation 10.18'!C6 -> 0 | D26: =-[5]Reco!F23 -> 0
B27: Add: Gratuity expense as per books | C27: ='Tax Computation 10.18'!C7 -> 0 | D27: =-[5]Reco!F15 -> 0
B28: Less: Gratuity paid | C28: ='Tax Computation 10.18'!C8 -> 0 | D28: =-[5]Reco!F14 -> 0
B29: Add: Leave expense as per books | C29: ='Tax Computation 10.18'!C9 -> 0 | D29: =-[5]Reco!F17 -> 0
B30: Less: Leave paid | C30: ='Tax Computation 10.18'!C10 -> 0 | D30: =-[5]Reco!F16 -> 0
B31: Less: Fair value gain on investments | C31: ='Tax Computation 10.18'!C11 -> 0 | D31: =-[5]Reco!F20 -> 0
B32: Add: Exchange loss/(gain) as per books | C32: ='Tax Computation 10.18'!C12 -> 0 | D32: =-[5]Reco!F22 -> 0
B33: Add: Realized exchange gain/(loss) | C33: ='Tax Computation 10.18'!C13 -> 0 | D33: =-[5]Reco!F21 -> 0
B34: Add: Difference in profit on sale of investment | C34: 0 | D34: 270000
B35: Add: Disallowed expenses | C35: ='Tax Computation 10.18'!C14 -> 0 | D35: 0
B36: Taxable profit | C36: =SUM(C23:C35) -> -33900 | D36: =SUM(D23:D35) -> 92904
B37: Income tax expense @ 25% | C37: =C36*25% -> -8475 | D37: =D36*25% -> 23226

Sheet 3.16 to 3.20 ao 10.18
A1: ='[5]3.3'!A1:E1 -> CELER MART PVT. LTD.
A3: Notes to Financial Statements
A5: Figures in NPR
A7: 3.21. Changes in Accounting Policies (If any)
A8: In the current financial year the company changes in accounting policies. This change has been accounted for by restating comparatives and adjusting the opening balance of retained earnings at 01 Shrawan 20XX. The changes in accounting policy, when applied consistently to 20X1 had the follwoing impact: On Opening Retained Earnings; On Net Profit.
A10: 3.18. Contingencies
A11: The company has contingent liabilities in respect of bank and other guarantees and other matters arising in the ordinary course of business. It is not anticipated that any material liablitites will arise from the contingent liabilities.
A13: 3.19. Related Party Transactions
A14: Identity of related parties
A15: The company is controlled by (name of the parent company) which owns xx percent of the company's shares. The remaining xx percent shares are widely held. The ultimate parent company of the company is (name of the ultimate parent company) incorporated in (name of the country)
A16: The following transactions were carried out with related parties (Give details)
A17: Directors of the company and their immediate relatives control xx percent of the voting shares of the company. Loans to directors amounting to NRs xx (20XX: NRs xx) are included in "other receivables". No interest is payable by the directors (for disclose if interest is payable)
A18: In additiona to their salaries, the company also provides non-cash benefits to directors and executive officers, and contributes to a post-employment defined benefit plan on their behalf.
... A27: Prior period errors are ommissions or misstatements in an entity's financial statements. Such ommissions may relate to one or more prior periods. Correction of an error is done by calculating the cumulative effect of the change on the financial statements of the period as if new method or estimate had always been used for all the affected prior years' financial statements. Sometimes, such changes may not be practicable, in such cases it is applied to the latest period possible by making corresponding adjustment to the opening balance of the period.

Sheet Annex 1&2 ao 10.18
A1: ='[5]3.3'!A1:E1 -> CELER MART PVT. LTD.
A3: Notes to Financial Statements
A5: Figures in NPR
A7: Significant Accounting Policies and Notes to Accounts
A9: 1. General information
A10: Give brief information about the legal status, registered address and nature of the business of the company.
A11: The financial statements were authorized to issue by …....... on …........
A13: 2. Significant Accounting Policies
A14: 2.1 Basis of preparation and accounting policies
A15: 2.1.1 Statement of Compliance
A16: These financial statements have been prepared in accordance with Nepal Accounting Standard for Micro Entities (NAS for MEs).
A17: 2.2.2 Basis of Measurement
A18: The financial statements have been prepared on the historical cost basis except investments held-for-trade is measured at fair value.
... A96: Interest expenses are recognized in the statement of income using accrual method.

Sheet Tax Computation 10.18
A1: CALCULATION OF TAXABLE INCOME
A3: Profit before tax as per books | C3: ='SOI 10.18'!C19 -> -164485.25
A4: Add: Depreciation as per books | C4: ='SOI 10.18'!C17 -> 130585.25
A5: Less: Depreciation as per tax | C5: 0
A6: Add: Disallowed repairs
A7: Add: Gratuity expense as per books
A8: Less: Gratuity paid
A9: Add: Leave expense as per books
A10: Less: Leave paid
A11: Less: Fair value gain on investments
A12: Add: Exchange loss as per books
A13: Add: Realized exchange gain
A14: Add: Disallowed expenses
A15: Taxable profit | C15: =SUM(C3:C14) -> -33900
A16: Income tax expense @ 25% | C16: 0

Sheet SOFP  03.15
A1: Magic Arun Hydropower Private Limitd
A2: Statement of Financial Position
A3: As at 15 Asadh 2083
F4: Restated
C5: As at | D5: As at | E5: As at | F5: As at
B6: Notes | C6: 15 Ashadh 2083 | D6: 18 Magh 2082 | E6: 32 Ashadh 2082 | F6: 1 Shrawan 2081
A7: ASSETS
A8: Non-Current Assets
A9: Property, Plant and Equipment | B9: 3.1 | C9: ='3.1 03.15'!I52 -> 473888.75 | D9: ='3.1 10.18'!I44 -> 473888.75 | E9: ='3.1 10.18'!I42 -> 604474 | F9: 0 | H9: =+E9+E11 -> 604474 | I9: =+C9+C11 -> 473888.75
A10: Project in Progress (WIP) | B10: 3.1 | C10: ='3.1 03.15'!C76 -> 17094931 | D10: ='3.1 10.18'!C70 -> 15814476 | E10: ='3.1 10.18'!F70 -> 12985641 | F10: ='3.1 10.18'!G50 -> 12985641
A11: Intangible Assets | B11: 3.2 | C11: ='[5]3.2'!E43 -> 0 | D11: ='[5]3.2'!F43 -> 0 | E11: ='[5]3.2'!E41 -> 0 | F11: ='[5]3.2'!E39 -> 0 | H11: 821236.13 | I11: =+'SOI 10.18'!C17 -> 130585.25
A12: Investments | B12: 3.3 | C12: ='[5]3.3'!C34 -> 0 | D12: ='[5]3.3'!D34 -> 0 | E12: ='[5]3.3'!D34 -> 0 | F12: ='[5]3.3'!E34 -> 0 | H12: =+H9-H11 -> -216762.13 | I12: =SUM(I9:I11) -> 604474
A13: Other Receivables | B13: 3.4 | C13: 0 | D13: 0 | E13: 0 | F13: 0 | I13: 2699634.6 | J13: =+I12-I13 -> -2095160.6
A14: Total Non-Current Assets | C14: =SUM(C9:C13) -> 17568820 | D14: =SUM(D9:D13) -> 16288365 | E14: =SUM(E9:E13) -> 13590115 | F14: =SUM(F9:F13) -> 12985641
A15: Current Assets
A16: Investments | B16: 3.3 | C16: ='[5]3.3'!C35 -> 0 | D16: ='[5]3.3'!D35 -> 0 | E16: ='[5]3.3'!D35 -> 0 | F16: ='[5]3.3'!E35 -> 0
A17: Account receivables | B17: 3.4 | C17: ='3.4 to 3.6 ao 03.15'!C36 -> 25069196 | D17: ='3.4 to 3.6 ao 10.18'!C32 -> 21010112 | E17: ='3.4 to 3.6 ao 10.18'!D32 -> 15311962 | F17: ='3.4 to 3.6 ao 10.18'!E32 -> 21788699 | H17: AS per Tally
A18: Inventories | B18: 3.5 | E18: =+'3.4 to 3.6 ao 10.18'!D47 -> 0 | F18: =+'3.4 to 3.6 ao 10.18'!E47 -> 0 | H18: 10922985
A19: Cash and cash equivalents | B19: 3.6 | C19: ='3.4 to 3.6 ao 03.15'!C62 -> 1615017.4 | D19: ='3.4 to 3.6 ao 10.18'!C58 -> 12637.35 | E19: ='3.4 to 3.6 ao 10.18'!D58 -> 891197 | F19: ='3.4 to 3.6 ao 10.18'!E58 -> 67329
A20: Other current assets | B20: 3.7 | C20: =+'3.4 to 3.6 ao 10.18'!C68 -> 0 | D20: =+'3.4 to 3.6 ao 10.18'!D68 -> 0 | E20: =+'3.4 to 3.6 ao 10.18'!D68 -> 0 | F20: =+'3.4 to 3.6 ao 10.18'!E68 -> 0
A21: Total Current Assets | C21: =SUM(C16:C20) -> 26684214 | D21: =SUM(D16:D20) -> 21022749 | E21: =SUM(E16:E20) -> 16203159 | F21: =SUM(F16:F20) -> 21856028
A22: Total Assets | C22: =C21+C14 -> 44253034 | D22: =D21+D14 -> 37311114 | E22: =E21+E14 -> 29793274 | F22: =F21+F14 -> 34841669
A23: EQUITY AND LIABILITIES
A24: Equity
A25: Share Capital | B25: 3.8 | C25: ='3.7 to 3.8 03.15'!D35 -> 44000000 | D25: ='3.7 to 3.8 10.18'!D31 -> 10290000 | E25: ='3.7 to 3.8 10.18'!E31 -> 12600000 | F25: 0 | H25: 6175421.8 | I25: =+H25+E27 -> 5801845.8
A26: Calls in Advance | C26: ='3.7 to 3.8 03.15'!D42 -> 500000 | D26: ='3.7 to 3.8 10.18'!D38 -> 22500000 | E26: 0 | F26: ='3.7 to 3.8 10.18'!E38 -> 0
A27: Retained Earnings | B27: 3.9 | C27: ='3.7 to 3.8 03.15'!D51 -> -571961.25 | D27: ='3.7 to 3.8 10.18'!D47 -> -538061.25 | E27: ='3.7 to 3.8 10.18'!E47 -> -373576 | F27: ='3.7 to 3.8 10.18'!E45 -> -196480 | H27: -6165121.9 | I27: =+H27-E27 -> -5791545.9
A28: Total Equity | C28: =SUM(C25:C27) -> 43928039 | D28: =SUM(D25:D27) -> 32251939 | E28: =SUM(E25:E27) -> 12226424 | F28: =SUM(F25:F27) -> -196480 | I28: 79025.12
A29: Liabilities
A30: Non-Current Liabilities
A31: Loans and Borrowings | B31: 3.10 | C31: ='3.9 to 3.11 AO 03.15'!C25 -> 40000 | D31: ='3.9 to 3.11 AO 10.18'!D25 -> 3870000 | E31: ='3.9 to 3.11 AO 10.18'!E25 -> 17165000 | F31: ='3.9 to 3.11 AO 10.18'!F25 -> 20756010
A32: Provision for Employee Benefits | C32: ='3.9 to 3.11 AO 10.18'!D36 -> 0 | D32: ='3.9 to 3.11 AO 10.18'!E36 -> 0 | E32: ='3.9 to 3.11 AO 10.18'!E36 -> 0 | F32: ='3.9 to 3.11 AO 10.18'!F36 -> 0
A33: Provisions | E33: 0 | F33: 0
A34: Total Non-Current Liabilities | C34: =SUM(C31:C33) -> 40000 | D34: =SUM(D31:D33) -> 3870000 | E34: =SUM(E31:E33) -> 17165000 | F34: =SUM(F31:F33) -> 20756010
A35: Current Liabilities
A36: Loans and Borrowings | B36: 3.10 | C36: ='3.9 to 3.11 AO 10.18'!D26 -> 0 | D36: ='3.9 to 3.11 AO 10.18'!E26 -> 0 | E36: ='3.9 to 3.11 AO 10.18'!E26 -> 0 | F36: ='3.9 to 3.11 AO 10.18'!F26 -> 0
A37: Trade and other payables | B37: 3.11 | C37: ='3.9 to 3.11 AO 03.15'!C50+'3.9 to 3.11 AO 03.15'!C63 -> 284995.2 | D37: ='3.9 to 3.11 AO 10.18'!D49+'3.9 to 3.11 AO 10.18'!D61 -> 1189175 | E37: ='3.9 to 3.11 AO 10.18'!E49 -> 401850 | F37: ='3.9 to 3.11 AO 10.18'!F49 -> 28498
A38: Income Tax Liability | C38: ='3.9 to 3.11 AO 10.18'!D69 -> 0 | D38: ='3.9 to 3.11 AO 10.18'!E69 -> 0 | E38: ='3.9 to 3.11 AO 10.18'!E69 -> 0 | F38: ='3.9 to 3.11 AO 10.18'!F69 -> 0
A39: Provision for Employee Benefits | C39: 0 | D39: 0 | E39: 0 | F39: 0
A40: Provisions | C40: 0 | D40: 0 | E40: 0 | F40: 0
...

Sheet SOI 03.15
A1: ='SOFP 10.18'!A1 -> Magic Arun Hydropower Private Limitd
A3: Statement of Income
A4: For the Year Ended 15 Asadh 2083
E5: Figures in NPR
E6: Restated
A7: Particulars | B7: Notes | C7: Upto 15 Asadh 2083 | D7: Upto 10 Magh 2082 | E7: FY 2081-82
A8: Revenue from Operations | B8: 3.12 | D8: ='3.12 to 3.18 ao 10.18'!D12 -> 0 | E8: ='3.12 to 3.18 ao 10.18'!E12 -> 0 | H8: =D8-E8 -> 0 | I8: =H8/E8 -> #DIV/0!
A9: Interest Income | D9: 0 | E9: 0
A10: Other Income | B10: 3.13 | D10: ='3.12 to 3.18 ao 10.18'!D21 -> 0 | E10: ='3.12 to 3.18 ao 10.18'!E21 -> 0
A11: Total Income | D11: =SUM(D8:D10) -> 0 | E11: =SUM(E8:E10) -> 0
A12: Material Consumed Expenses | B12: 3.14 | D12: ='3.12 to 3.18 ao 10.18'!D30 -> 0 | E12: ='3.12 to 3.18 ao 10.18'!E30 -> 0 | F12: =(D12+D13)/D8 -> #DIV/0! | G12: =(E12+E13)/E8 -> #DIV/0! | H12: =D12-E12 -> 0 | I12: =H12/E12 -> #DIV/0!
A13: Direct Expenses | B13: 3.15 | D13: =+'3.12 to 3.18 ao 10.18'!D38 -> 0 | E13: =+'3.12 to 3.18 ao 10.18'!E38 -> 0 | H13: =D13-E13 -> 0 | I13: =H13/E13 -> #DIV/0!
A14: Employee Benefit Expenses | B14: 3.16 | D14: =+'3.12 to 3.18 ao 10.18'!D50 -> 0 | E14: =+'3.12 to 3.18 ao 10.18'!E50 -> 0 | H14: =D14-E14 -> 0 | I14: =H14/E14 -> #DIV/0!
A15: Administrative and Other Expenses | B15: 3.17 | D15: ='3.12 to 3.18 ao 10.18'!D81 -> 33900 | E15: ='3.12 to 3.18 ao 10.18'!E81 -> 29382 | H15: =D15-E15 -> 4518 | I15: =H15/E15 -> 0.15376761
A16: Interest Expenses | B16: 3.18 | D16: ='3.12 to 3.18 ao 10.18'!D86 -> 0 | E16: ='3.12 to 3.18 ao 10.18'!E86 -> 0 | H16: =D16-E16 -> 0 | I16: =H16/E16 -> #DIV/0!
A17: Depreciation and Amortization Expenses | B17: 3.1 & 3.2 | D17: 0 | E17: =+'3.1 10.18'!I28+'[5]3.2'!E30 -> 147714 | F17: 187078.71 | G17: =+E17-F17 -> -39364.71 | H17: =D17-E17 -> -147714 | I17: =H17/E17 -> -1
A18: Total Expenses | D18: =SUM(D12:D17) -> 33900 | E18: =SUM(E12:E17) -> 177096
A19: Profit Before Tax | D19: =D11-D18 -> -33900 | E19: =E11-E18 -> -177096 | F19: -2368782.9 | G19: =+E19-F19 -> 2191686.9
A20: Income Tax Expense | D20: =SUM(D21:D22) -> 0 | E20: =SUM(E21:E22) -> 0
A21: Current year | D21: 0 | E21: 0
A22: Previous years | D22: 0 | E22: 0
A23: Net Profit for the year | D23: =D19-D20 -> -33900 | E23: =E19-E20 -> -177096

Sheet SOCE 03.15
A1: ='SOI 10.18'!A1 -> Magic Arun Hydropower Private Limitd
A3: Statement of Changes in Equity
A4: ='SOI 10.18'!A4 -> For the Year Ended 18 Magh 2082
G6: Figures in NPR
A7: Particulars | C7: Share Capital | D7: Calls in Advance | E7: Retained Earnings | F7: Other Reserves | G7: Total
A8: Balance at 1 Shrawan 2081 | C8: =+'SOFP 10.18'!E25 -> 0 | D8: 7600000 | E8: =+'3.7 to 3.8 10.18'!E45 -> -196480 | F8: 0 | G8: =SUM(C8:F8) -> 7403520
A9: Restatements on transition to NAS for MEs | C9: 0 | D9: 0 | E9: =SUM([5]Reco!F5:F8) -> 0 | F9: 0 | G9: =SUM(C9:F9) -> 0
A10: Balance at 1 Shrawan 2081 (restated) | C10: =SUM(C8:C9) -> 0 | D10: =SUM(D8:D9) -> 7600000 | E10: =SUM(E8:E9) -> -196480 | F10: =SUM(F8:F9) -> 0 | G10: =SUM(G8:G9) -> 7403520 | H10: ='SOFP 10.18'!E28 -> -196480 | I10: =G10-H10 -> 7600000
A11: Profit for the year | C11: 0 | D11: 0 | E11: ='SOI 10.18'!D23 -> -177096 | F11: 0 | G11: =+SUM(C11:F11) -> -177096
A12: Issue of Shares | C12: 12600000 | D12: -7600000 | E12: 0 | F12: 0 | G12: =+SUM(C12:F12) -> 5000000
A13: Dividends to Shareholders | C13: 0 | D13: 0 | E13: 0 | F13: 0 | G13: =+SUM(C13:F13) -> 0
A14: Other Changes | C14: 0 | D14: 0 | E14: 0 | F14: 0 | G14: =+SUM(C14:F14) -> 0
A15: Balance at 32 Ashad 2082 | C15: =SUM(C10:C14) -> 12600000 | D15: =SUM(D10:D14) -> 0 | E15: =SUM(E10:E14) -> -373576 | F15: =SUM(F10:F14) -> 0 | G15: =SUM(G10:G14) -> 12226424 | H15: ='SOFP 10.18'!D28 -> 12226424 | I15: =G15-H15 -> 0
A16: Profit for the year | C16: 0 | D16: 0 | E16: =+'SOI 10.18'!C23 -> -164485.25 | F16: 0 | G16: =+SUM(C16:F16) -> -164485.25
A17: Issue of Shares | C17: 0 | D17: 0 | E17: 0 | F17: 0 | G17: =+SUM(C17:F17) -> 0
A18: Dividends to Shareholders | C18: 0 | D18: 0 | E18: 0 | F18: 0 | G18: =+SUM(C18:F18) -> 0
A19: Other Changes | C19: 0 | D19: 0 | E19: 0 | F19: 0 | G19: =+SUM(C19:F19) -> 0
A20: Balance at 32 Ashad 2083 | C20: =SUM(C15:C19) -> 12600000 | D20: =SUM(D15:D19) -> 0 | E20: =SUM(E15:E19) -> -538061.25 | F20: =SUM(F15:F19) -> 0 | G20: =SUM(G15:G19) -> 12061939 | H20: ='SOFP 10.18'!C28 -> 32251939 | I20: =G20-H20 -> -20190000

Sheet SCF 03.15
A1: ='SOCE 10.18'!A1 -> Magic Arun Hydropower Private Limitd
A3: Statement of Cash Flows
A4: ='SOCE 10.18'!A4 -> For the Year Ended 18 Magh 2082
C5: Figures in NPR
A6: Particulars | B6: ='SOI 10.18'!C7 -> Upto 18 Magh 2082 | C6: ='SOI 10.18'!D7 -> FY 2081-82
A7: CASH FLOWS FROM OPERATING ACTIVITIES
A8: Profit for the year | B8: ='SOI 10.18'!C19 -> -164485.25 | C8: ='SOI 10.18'!D19 -> -177096 | D8: =B8-'SOFP 10.18'!J27 -> -164485.25
A9: Adjustment for:
A10: Depreciation/Impairment on Property, Plant and Equipment | B10: ='SOI 10.18'!C17 -> 130585.25 | C10: ='SOI 10.18'!D17 -> 147714
A11: Interest Income
A12: Interest Expense | B12: ='SOI 10.18'!C16 -> 0 | C12: ='SOI 10.18'!D16 -> 0
A13: Loss/(gain) on sale of Property, Plant and Equipment
A14: Income Tax expense charged to statement of income
A15: Working Capital Adjustments
A16: Decrease/(Increase) in trade and other receivables | B16: ='SOFP 10.18'!J17+'SOFP 10.18'!J20 -> 0 | C16: ='SOFP 10.18'!E17-'SOFP 10.18'!D17 -> 6476737
A17: Decrease/(Increase) in Inventories | B17: ='SOFP 10.18'!J18 -> 0 | C17: ='SOFP 10.18'!K18 -> 0
A18: Increase/(Decrease) in trade and other payables | B18: ='SOFP 10.18'!J37 -> 0 | C18: ='SOFP 10.18'!K37 -> 0
A19: Increase/(Decrease) Loan and Borrowings | C19: ='SOFP 10.18'!D31-'SOFP 10.18'!E31 -> -3591010
A20: Increase/(Decrease) in other liabilities | C20: 0
A21: Cash Generated from Operations | B21: =SUM(B8:B20) -> -33900 | C21: =SUM(C8:C20) -> 2856345
A22: Interest paid | C22: 0
A23: Income tax paid | C23: 0
A24: NET CASH FLOWS FROM OPERATING ACTIVITIES (A) | B24: =SUM(B21:B23) -> -33900 | C24: =SUM(C21:C23) -> 2856345
A25: CASH FLOW FROM INVESTING ACTIVITIES
A26: Proceeds from sale of PPE, Investments/Financial Assets | C26: =-'3.1 10.18'!I8 -> 0
A27: Increase in project WIP | B27: ='SOFP 10.18'!J12 -> 0 | C27: =-'SOFP 10.18'!D10+'SOFP 10.18'!E10 -> 0
A28: Acquisition of Property, Plant and Equipment | B28: =-'3.1 10.18'!I15-'[5]3.2'!E17 -> 0 | C28: =-'3.1 10.18'!I10-'[5]3.2'!E12 -> -752188
A29: NET CASH FLOWS FROM INVESTING ACTIVITIES (B) | B29: =SUM(B25:B28) -> 0 | C29: =SUM(C25:C28) -> -752188
A30: CASH FLOW FROM FINANCING ACTIVITIES
A31: Proceeds from the issue of Equity and Preference Share | C31: ='SOFP 10.18'!D25-'SOFP 10.18'!E26 -> 12600000
A32: Proceeds from loans and borrowings borrowings | B32: ='SOFP 10.18'!J36 -> 0 | C32: ='SOFP 10.18'!K36 -> 0
A33: Interest Expenses | B33: =-B12 -> 0 | C33: =-C12 -> 0
A34: Dividend Paid
A35: NET CASH FLOW FROM FINANCING ACTIVITIES (C) | B35: =SUM(B31:B34) -> 0 | C35: =SUM(C31:C34) -> 12600000
A36: Net Increase in Cash and Cash Equivalents | B36: =B24+B29+B35 -> -33900 | C36: =C24+C29+C35 -> 14704157
A37: Cash and Cash Equivalents at the beginning | B37: ='SOFP 10.18'!D19 -> 891197 | C37: ='SOFP 10.18'!E19 -> 67329
A38: Exchange gains/(losses) in cash and cash equivalents
A39: Cash and Cash Equivalents at the end | B39: =B36+B37 -> 857297 | C39: =C36+C37 -> 14771486
B40: ='3.4 to 3.6 ao 10.18'!C58 -> 12637.35 | C40: ='3.4 to 3.6 ao 10.18'!D58 -> 891197
B41: =B39-B40 -> 844659.65 | C41: =C39-C40 -> 13880289

Sheet 3.1 03.15
A1: ='SOFP 10.18'!A1 -> Magic Arun Hydropower Private Limitd
A2: Notes to Financial Statements
I3: Figures in NPR
A4: 3.1 | B4: Property, Plant and Equipment
C5: Furniture & Fixtures | D5: Computer | E5: Office Equipments | F5: Vehicles | G5: Plant and Machinery | H5: Office Furnishing | I5: Total
B6: Cost
B8: Balance at 1 Shrawan 2081 | C8: 0 | D8: 0 | E8: 0 | F8: 0 | G8: 0 | I8: =SUM(C8:G8) -> 0
I9: =SUM(C9:G9) -> 0
B10: Additions | C10: 532188 | D10: 0 | E10: 0 | F10: 220000 | G10: 0 | I10: =SUM(C10:G10) -> 752188
B11: Disposals | C11: 0 | D11: 0 | E11: 0 | F11: 0 | G11: 0 | I11: =SUM(C11:G11) -> 0
B13: Balance at 32 Ashadh 2082 | C13: =SUM(C8:C11) -> 532188 | D13: =SUM(D8:D11) -> 0 | E13: =SUM(E8:E11) -> 0 | F13: =SUM(F8:F11) -> 220000 | G13: =SUM(G8:G11) -> 0 | I13: =SUM(I8:I11) -> 752188
B15: Additions | C15: 0 | E15: 0 | G15: 0 | I15: =SUM(C15:G15) -> 0
B16: Disposals | C16: 0 | D16: 0 | E16: 0 | F16: 0 | G16: 0 | I16: =SUM(C16:G16) -> 0
B18: Balance at 18 Magh 2082 | C18: =SUM(C13:C16) -> 532188 | D18: =SUM(D13:D16) -> 0 | E18: =SUM(E13:E16) -> 0 | F18: =SUM(F13:F16) -> 220000 | G18: =SUM(G13:G16) -> 0 | H18: =SUM(H13:H16) -> 0 | I18: =SUM(C18:G18) -> 752188
B20: Additions
B21: Disposals
B23: Balance at 15 Asadh 2083 | C23: =SUM(C18:C21) -> 532188 | D23: =SUM(D18:D21) -> 0 | E23: =SUM(E18:E21) -> 0 | F23: =SUM(F18:F21) -> 220000 | G23: =SUM(G18:G21) -> 0 | H23: =SUM(H18:H21) -> 0 | I23: =SUM(I18:I21) -> 752188
B25: Accumulated depreciation
B27: =B8 -> Balance at 1 Shrawan 2081 | C27: 0 | D27: 0 | E27: 0 | F27: 0 | G27: 0 | I27: =SUM(C27:G27) -> 0
B29: Charge for the year | C29: 133047 | D29: 0 | E29: 0 | F29: 14667 | G29: 0 | H29: 0 | I29: =SUM(C29:H29) -> 147714
B30: Disposals
B32: =B13 -> Balance at 32 Ashadh 2082 | C32: =SUM(C27:C30) -> 133047 | D32: =SUM(D27:D30) -> 0 | E32: =SUM(E27:E30) -> 0 | F32: =SUM(F27:F30) -> 14667 | G32: =SUM(G27:G30) -> 0 | H32: =SUM(H27:H30) -> 0 | I32: =SUM(I27:I30) -> 147714
B34: Charge for the year | C34: =(C13-C29)*25% -> 99785.25 | E34: 0 | F34: 30800 | G34: 0 | H34: =(H18-H32)*15% -> 0 | I34: =SUM(C34:G34) -> 130585.25
B35: Disposals
B37: =B18 -> Balance at 18 Magh 2082 | C37: =C34+C32 -> 232832.25 | D37: =SUM(D32:D35) -> 0 | E37: =SUM(E32:E35) -> 0 | F37: =F34+F32 -> 45467 | G37: =SUM(G32:G35) -> 0 | H37: =SUM(H32:H35) -> 0 | I37: =SUM(C37:G37) -> 278299.25
B39: Charge for the year
B40: Disposals
B42: Balance at 15 Asadh 2083 | C42: =C39+C37 -> 232832.25 | D42: =D39+D37 -> 0 | E42: =E39+E37 -> 0 | F42: =F39+F37 -> 45467 | G42: =G39+G37 -> 0 | H42: =H39+H37 -> 0 | I42: =I39+I37 -> 278299.25
B44: Net Book Value
B46: As at 1st Shrawan 2081 | C46: =C8-C27 -> 0 | D46: =D8-D27 -> 0 | E46: =E8-E27 -> 0 | F46: =F8-F27 -> 0 | G46: =G8-G27 -> 0 | H46: =H8-H27 -> 0 | I46: =I8-I27 -> 0
B48: As at 32nd Ashad 2082 | C48: =C13-C32 -> 399141 | D48: =D13-D32 -> 0 | E48: =E13-E32 -> 0 | F48: =F13-F32 -> 205333 | G48: =G13-G32 -> 0 | H48: =H13-H32 -> 0 | I48: =SUM(C48:G48) -> 604474
B50: As at 18 Magh 2082 | C50: =C18-C37 -> 299355.75 | D50: =D18-D37 -> 0 | E50: =E18-E37 -> 0 | F50: =F18-F37 -> 174533 | G50: =G18-G37 -> 0 | H50: =H18-H37 -> 0 | I50: =SUM(C50:G50) -> 473888.75
B52: As at 15 Asadh 2083 | C52: =C23-C42 -> 299355.75 | D52: =D23-D42 -> 0 | E52: =E23-E42 -> 0 | F52: =F23-F42 -> 174533 | G52: =G23-G42 -> 0 | H52: =H23-H42 -> 0 | I52: =I23-I42 -> 473888.75
B54: 3.1.2 Project in Progress (WIP)
B55: Particulars | C55: As on 10 Magh 2082 | E55: During the period | G55: 2080.081
B56: Project Initial Expenses | C56: =C76 -> 17094931 | E56: =D76 -> 1280455.2 | G56: =F76 -> 15814476
C58: As on 15 Asadh 2083 | D58: During the period | F58: As on 10 Magh 2082
B59: Survey License Fee | C59: =F59+D59 -> 8000000 | D59: ='TB update upto 10.18'!I59 -> 0 | F59: ='TB update upto 10.18'!G59 -> 8000000
B60: License Renewal Fee | C60: =F60+D60 -> 2000000 | D60: ='TB update upto 10.18'!I60 -> 0 | F60: ='TB update upto 10.18'!G60 -> 2000000
B61: PPA Fee | C61: =F61+D61 -> 300000 | D61: ='TB update upto 10.18'!I61 -> 0 | F61: ='TB update upto 10.18'!G61 -> 300000
...

Sheet TB update upto 10.18
E1: =E108-F108 -> 0
B2: Particulars | C2: Opening as on 2082.04.01 | D2: Opening as on 04.01 | E2: During the Year | G2: Closing as on 2082.10.18 | H2: Closing as on 2082.10.18 | I2: During 10.19 to 03.15 | J2: During 10.19 to 03.15 | K2: Closing as on 03.15 | M2: During 03.15 to 03.32 | O2: Closing as on 03.32 | P2: Cosing as on 03.32
C3: Dr | D3: Cr | E3: Dr | F3: Cr | G3: Dr | H3: Cr | I3: Dr. | J3: Cr. | K3: Dr. | L3: Cr. | M3: Dr. | N3: Cr | O3: Dr. | P3: Cr.
B4: Reserve & Surplus | C4: 373575.67 | G4: =C4-D4+E4-F4 -> 373575.67 | K4: =G4-H4+I4-J4 -> 373575.67 | O4: =K4-L4+M4-N4 -> 373575.67
B5: Share Capital
B6: I.B. Multipurpose Pvt Ltd | I6: ='TB 10.18 to 03.15'!B9 -> 0 | J6: ='TB 10.18 to 03.15'!C9 -> 15000000 | L6: =H6-G6+J6-I6 -> 15000000 | P6: =L6-K6+N6-M6 -> 15000000
B7: Happy Nepal Investment | I7: ='TB 10.18 to 03.15'!B10 -> 0 | J7: ='TB 10.18 to 03.15'!C10+D137 -> 25000000 | L7: =H7-G7+J7-I7 -> 25000000 | P7: =L7-K7+N7-M7 -> 25000000
B8: Indra Bahadur Bista | I8: ='TB 10.18 to 03.15'!B21 -> 0 | J8: ='TB 10.18 to 03.15'!C21 -> 1500000 | L8: =H8-G8+J8-I8 -> 1500000 | P8: =L8-K8+N8-M8 -> 1500000
B9: Tanka Prasad Pandey | I9: ='TB 10.18 to 03.15'!B22 -> 0 | J9: ='TB 10.18 to 03.15'!C22 -> 2500000 | L9: =H9-G9+J9-I9 -> 2500000 | P9: =L9-K9+N9-M9 -> 2500000
B10: Rajendra Karki | D10: 3200000 | E10: ='TB 2082.04.01-10.18'!D6 -> 2310000 | F10: ='TB 2082.04.01-10.18'!E6 -> 0 | H10: =D10-C10+F10-E10 -> 890000 | I10: ='TB 10.18 to 03.15'!B7 -> 2380000 | J10: ='TB 10.18 to 03.15'!C7 -> 0 | K10: =G10-H10+I10-J10 -> 1490000 | O10: =K10-L10+M10-N10 -> 1490000
B11: Bijay Bista | D11: 3200000 | E11: =+C119 -> 3200000 | F11: ='TB 2082.04.01-10.18'!E7 -> 0 | G11: =C11-D11+E11-F11 -> 0 | H11: =D11-C11+F11-E11 -> 0
B12: Kanchan Sherpa | D12: 200000 | E12: =C120 -> 200000 | G12: =C12-D12+E12-F12 -> 0 | H12: =D12-C12+F12-E12 -> 0
B13: Lilamani Pathak | D13: 1000000 | E13: =C121 -> 1000000 | G13: =C13-D13+E13-F13 -> 0 | H13: =D13-C13+F13-E13 -> 0
B14: Bhadra Ventures Pvt. Ltd. | D14: 5000000 | E14: =C122 -> 5000000 | G14: =C14-D14+E14-F14 -> 0 | H14: =D14-C14+F14-E14 -> 0
B15: Share - Shivaram Bhandari | F15: =D123 -> 5000000 | H15: =D15-C15+F15-E15 -> 5000000 | I15: =C133 -> 5000000 | L15: =H15-G15+J15-I15 -> 0 | P15: =L15-K15+N15-M15 -> 0
B16: Share - Indu Bhandari Basnet | F16: =D124 -> 2510000 | H16: =D16-C16+F16-E16 -> 2510000 | I16: =C134 -> 2510000 | L16: =H16-G16+J16-I16 -> 0 | P16: =L16-K16+N16-M16 -> 0
B17: Share - Nabaraj Tiwari | F17: =D125 -> 1260000 | H17: =D17-C17+F17-E17 -> 1260000 | I17: =C135 -> 1260000 | L17: =H17-G17+J17-I17 -> 0 | P17: =L17-K17+N17-M17 -> 0
B18: Share - Murali Adhikari | F18: =D126 -> 630000 | H18: =D18-C18+F18-E18 -> 630000 | I18: =C136 -> 630000 | L18: =H18-G18+J18-I18 -> 0 | P18: =L18-K18+N18-M18 -> 0
B19: Advance for Share Capital
B20: Share Advance - Shiv Ram Bhandari | E20: ='TB 2082.04.01-10.18'!D36 -> 0 | F20: ='TB 2082.04.01-10.18'!E36 -> 20000000 | H20: =D20-C20+F20-E20 -> 20000000 | I20: =C151+C162 -> 20600000 | J20: =D168 -> 600000 | L20: =H20-G20+J20-I20 -> 0 | P20: =L20-K20+N20-M20 -> 0
B21: Share Advance - Bond Construction | E21: ='TB 2082.04.01-10.18'!D38 -> 0 | F21: ='TB 2082.04.01-10.18'!E38 -> 2000000 | H21: =D21-C21+F21-E21 -> 2000000 | I21: =C171 -> 2000000 | L21: =H21-G21+J21-I21 -> 0 | P21: =L21-K21+N21-M21 -> 0
B22: Share Advance - Uttam Kumar | F22: ='TB 2082.04.01-10.18'!E28 -> 500000 | H22: =D22-C22+F22-E22 -> 500000 | L22: =H22-G22+J22-I22 -> 500000 | P22: =L22-K22+N22-M22 -> 500000
B23: Share Advance - Naresh Paudel | H23: 0 | L23: =H23-G23+J23-I23 -> 0 | P23: =L23-K23+N23-M23 -> 0
B24: Current Liabilities
B25: Duties & Taxes
B26: TDS on Audit fee | D26: 375 | F26: 450 | H26: =D26-C26+F26-E26 -> 825 | I26: =C141 -> 375 | J26: 450 | L26: =H26-G26+J26-I26 -> 900 | P26: =L26-K26+N26-M26 -> 900
B27: TDS on Salary (SST) | D27: 25750 | E27: ='TB 2082.04.01-10.18'!D13 -> 0 | F27: ='TB 2082.04.01-10.18'!E13 -> 4150 | H27: =D27-C27+F27-E27 -> 29900 | I27: =C142 -> 25750 | J27: ='TB 10.18 to 03.15'!C16+D181+D202 -> 9270.202 | L27: =H27-G27+J27-I27 -> 13420.202 | P27: =L27-K27+N27-M27 -> 13420.202
B28: TDS 15% | E28: ='TB 2082.04.01-10.18'!D31 -> 0 | F28: ='TB 2082.04.01-10.18'!E31 -> 7275 | H28: =D28-C28+F28-E28 -> 7275 | L28: =H28-G28+J28-I28 -> 7275 | M28: ='TB After 03.15'!B12 -> 0 | N28: ='TB After 03.15'!C12 -> 2250 | P28: =L28-K28+N28-M28 -> 9525
B29: TDS Pvt Ltd | E29: ='TB 2082.04.01-10.18'!D24 -> 0 | F29: ='TB 2082.04.01-10.18'!E24 -> 0 | I29: ='TB 10.18 to 03.15'!B20 -> 0 | J29: ='TB 10.18 to 03.15'!C20 -> 4500 | L29: =H29-G29+J29-I29 -> 4500 | M29: ='TB After 03.15'!B3 -> 0 | N29: ='TB After 03.15'!C3 -> 7235.625 | P29: =L29-K29+N29-M29 -> 11735.625
B30: TDS on office Rent | D30: 24000 | H30: =D30-C30+F30-E30 -> 24000 | I30: =C143 -> 24000 | L30: =H30-G30+J30-I30 -> 0 | P30: =L30-K30+N30-M30 -> 0
B31: TDS on Labour Wages | D31: 6600 | H31: =D31-C31+F31-E31 -> 6600 | I31: =C144 -> 6600 | L31: =H31-G31+J31-I31 -> 0 | P31: =L31-K31+N31-M31 -> 0
B32: Expenses Payable
B33: Audit Fee payable | D33: 27875 | F33: 33450 | H33: =D33-C33+F33-E33 -> 61325 | I33: =C145 -> 27875 | J33: 33450 | L33: =H33-G33+J33-I33 -> 66900 | P33: =L33-K33+N33-M33 -> 66900
B34: Gajulkot Engineering And Construction Pvt. Ltd. | M34: ='TB After 03.15'!B4 -> 0 | N34: ='TB After 03.15'!C4 -> 537848.12 | P34: =L34-K34+N34-M34 -> 537848.12
B35: Pragya Travels And Tours Pvt Ltd | M35: ='TB After 03.15'!B8 -> 0 | N35: ='TB After 03.15'!C8 -> 115990 | P35: =L35-K35+N35-M35 -> 115990
B36: Samyog Bashyal | M36: ='TB After 03.15'!B13 -> 0 | N36: ='TB After 03.15'!C13 -> 22061 | P36: =L36-K36+N36-M36 -> 22061
B37: Staff Payable | D37: 222750 | H37: =D37-C37+F37-E37 -> 222750 | I37: =C185 -> 222750 | L37: =H37-G37+J37-I37 -> 0 | P37: =L37-K37+N37-M37 -> 0
B38: Office Rent Payable | D38: 94500 | H38: =D38-C38+F38-E38 -> 94500 | I38: =C186 -> 94500 | L38: =H38-G38+J38-I38 -> 0 | P38: =L38-K38+N38-M38 -> 0
B39: Loan & Borrowings
B40: Naresh Poudel-Payable | D40: 365000 | F40: ='TB 2082.04.01-10.18'!E21 -> 25000 | H40: =D40-C40+F40-E40 -> 390000 | I40: =C190 -> 350000 | L40: =H40-G40+J40-I40 -> 40000 | P40: =L40-K40+N40-M40 -> 40000
...

Sheet 3.9 to 3.11 AO 03.15
A1: ='[5]3.3'!A1:E1 -> CELER MART PVT. LTD.
A3: Notes to Financial Statements
F5: Figures in NPR
A7: 3.9 | B7: Loans and Borrowings
C8: As at | D8: ='3.7 to 3.8 10.18'!D8 -> As at | E8: ='3.7 to 3.8 10.18'!E8 -> As at | F8: =E8 -> As at
C9: 15 Asadh 2083 | D9: ='SOFP 10.18'!C6 -> 18 Magh 2082 | E9: ='SOFP 10.18'!D6 -> 32 Ashadh 2082 | F9: ='SOFP 10.18'!E6 -> 1 Shrawan 2081
B10: Total Loans and Borrowings
B11: Bank Overdraft | D11: 0 | E11: 0 | F11: 0
B12: Short Term Payable | D12: 0 | E12: 0 | F12: 20756010
B13: Basudev Dhiktta | D13: ='TB update upto 10.18'!H49 -> 2200000 | E13: 2200000
B14: Bhadra Ventures Pvt.Ltd | D14: 0 | E14: 1300000
B15: Eak Raj Khatiwada | E15: 12000000
B16: Naresh Poudel-Payable | C16: ='TB update upto 10.18'!L40 -> 40000 | D16: ='TB update upto 10.18'!H40 -> 390000 | E16: 365000
B17: Sandipa Thapa | D17: ='TB update upto 10.18'!H41 -> 200000 | E17: 200000
B18: Shyam Prasad Kuikel | D18: ='TB update upto 10.18'!H42 -> 500000 | E18: 500000
B19: Ellite Wire Pvt.Ltd | D19: ='TB update upto 10.18'!H47 -> 380000 | E19: 600000
B20: Ellite Powers Pvt.Ltd | D20: ='TB update upto 10.18'!H89 -> 200000 | E20: 0
C23: =SUM(C11:C20) -> 40000 | D23: =SUM(D11:D20) -> 3870000 | E23: =SUM(E11:E20) -> 17165000 | F23: =SUM(F11:F19) -> 20756010
B25: Non-current loans and borrowings | C25: =C23-C26 -> 40000 | D25: =D23-D26 -> 3870000 | E25: =E23-E26 -> 17165000 | F25: =F23-F26 -> 20756010
B26: Current loans and borrowings | C26: =C11 -> 0 | D26: =D11 -> 0 | E26: =E11 -> 0 | F26: =F11 -> 0
A29: 3.10 | B29: Provision for Employee Benefits
C31: =C8 -> As at | D31: =D8 -> As at | E31: =E8 -> As at | F31: =F8 -> As at
C32: =C9 -> 15 Asadh 2083 | D32: =D9 -> 18 Magh 2082 | E32: =E9 -> 32 Ashadh 2082 | F32: =F9 -> 1 Shrawan 2081
B34: Provision for Gratuity | D34: 0 | E34: 0
B35: Provision for Leave benefits
C36: =SUM(C34:C35) -> 0 | D36: =SUM(D34:D35) -> 0 | E36: =SUM(E34:E35) -> 0 | F36: =SUM(F34:F35) -> 0
A38: 3.11 | B38: Trade and other payables
C39: =C31 -> As at | D39: =D31 -> As at | E39: =E31 -> As at | F39: =F31 -> As at
C40: =C32 -> 15 Asadh 2083 | D40: =D32 -> 18 Magh 2082 | E40: =E32 -> 32 Ashadh 2082 | F40: =F32 -> 1 Shrawan 2081
B41: TDS on Audit Fee | C41: ='TB update upto 10.18'!L26 -> 900 | D41: ='TB update upto 10.18'!H26 -> 825 | E41: 375 | F41: 375
B42: TDS on Salary (SST) | C42: ='TB update upto 10.18'!L27 -> 13420.202 | D42: ='TB update upto 10.18'!H27 -> 29900 | E42: 25750 | F42: 248
B43: TDS on Office Rent | D43: ='TB update upto 10.18'!H30 -> 24000 | E43: 24000 | F43: 0 | G43: Net of TDS
B44: TDS on Labour Wages | D44: ='TB update upto 10.18'!H31 -> 6600 | E44: 6600 | F44: 0
B45: Audit Fee Payable | C45: ='TB update upto 10.18'!L33 -> 66900 | D45: ='TB update upto 10.18'!H33 -> 61325 | E45: 27875 | F45: 27875
B46: Staff Payable | D46: ='TB update upto 10.18'!H37 -> 222750 | E46: 222750 | F46: 0
B47: Office Rent Payable | D47: ='TB update upto 10.18'!H38 -> 94500 | E47: 94500 | F47: 0
B48: TDS on Meeting Fee | C48: ='TB update upto 10.18'!L28 -> 7275 | D48: ='TB update upto 10.18'!H28 -> 7275
B49: TDS Pvt. Ltd. | C49: ='TB update upto 10.18'!L29 -> 4500
C50: =SUM(C41:C49) -> 92995.202 | D50: =SUM(D41:D49) -> 447175 | E50: =SUM(E41:E47) -> 401850 | F50: =SUM(F41:F47) -> 28498
B51: Other payable
...

Sheet 3.7 to 3.8 03.15
A1: ='[5]3.3'!A1:E1 -> CELER MART PVT. LTD.
B3: Notes to Financial Statements
F5: Figures in NPR
A7: 3.7 | B7: Share Capital
D8: As at | E8: ='3.4 to 3.6 ao 10.18'!D6 -> As at | F8: ='3.4 to 3.6 ao 10.18'!E6 -> As at
D9: 15 Asadh 2083 | E9: ='3.4 to 3.6 ao 10.18'!C7 -> 18 Magh 2082 | F9: ='3.4 to 3.6 ao 10.18'!D7 -> 32 Ashadh 2082
B11: Authorized
B12: 260,000 ordinary shares of NPR 100 each | E12: 26000000 | F12: =E12 -> 26000000
B14: Ordinary Shares Issued and Fully Paid
B15: Ordinary shares of Rs. 100 each
E16: Ordinary | F16: Ordinary
E17: share | F17: share capital
D18: As at | E18: As at | F18: As at
D19: 15 Asadh 2083 | E19: 10 Magh 2082 | F19: 32 Ashadh 2082
B20: Paid up Share capital
B21: Bijay Bista | F21: 3200000
B22: Rajendra Karki | E22: ='TB update upto 10.18'!H10 -> 890000 | F22: 3200000
B23: Kanchan Sherpa | F23: 200000
B24: Lilamani Pathak | F24: 1000000
B25: Bhadra Ventures Pvt.LTD | F25: 5000000
B26: Shivaram Bhandari | E26: ='TB update upto 10.18'!H15 -> 5000000
B27: Indu Bhandari Basnet | E27: ='TB update upto 10.18'!H16 -> 2510000
B28: Nabaraj Tiwari | E28: ='TB update upto 10.18'!H17 -> 1260000
B29: Murali Adhikari | E29: ='TB update upto 10.18'!H18 -> 630000
B30: I.B. Multipurpose Pvt Ltd | D30: ='TB update upto 10.18'!L6 -> 15000000
B31: Happy Nepal Investment | D31: ='TB update upto 10.18'!L7 -> 25000000
B32: Indra Bahadur Bista | D32: ='TB update upto 10.18'!L8 -> 1500000
B33: Tanka Prasad Pandey | D33: ='TB update upto 10.18'!L9 -> 2500000
B35: Total | D35: =SUM(D30:D34) -> 44000000 | E35: =SUM(E21:E34) -> 10290000 | F35: =SUM(F21:F34) -> 12600000
D36: As at | E36: As at | F36: As at
B37: Share Advance | D37: 15 Asadh 2083 | E37: 10 Magh 2082 | F37: 32 Ashadh 2082
B38: Shiv Ram Bhandari | D38: ='TB update upto 10.18'!L20 -> 0 | E38: ='TB update upto 10.18'!H20 -> 20000000
B39: Bond Construction | D39: ='TB update upto 10.18'!L21 -> 0 | E39: ='TB update upto 10.18'!H21 -> 2000000
B40: Uttam Kumar | D40: ='TB update upto 10.18'!L22 -> 500000 | E40: ='TB update upto 10.18'!H22 -> 500000
B41: Lilamani Pathak
B42: Total | D42: =SUM(D38:D41) -> 500000 | E42: =SUM(E38:E41) -> 22500000 | F42: =SUM(F38:F41) -> 0
A44: 3.8 | B44: Retained Earnings
D46: As at | E46: =E8 -> As at | F46: =F8 -> As at
D47: 15 Asadh 2083 | E47: ='SOFP 10.18'!C6 -> 18 Magh 2082 | F47: ='SOFP 10.18'!D6 -> 32 Ashadh 2082 | H47: New | K47: Old
